[2024-06-18 20:30:55,755: INFO/MainProcess] Connected to redis://redis:6379/0
[2024-06-18 20:30:55,757: INFO/MainProcess] mingle: searching for neighbors
[2024-06-18 20:30:56,765: INFO/MainProcess] mingle: all alone
[2024-06-18 20:30:56,778: INFO/MainProcess] celery@f0e3b3bba678 ready.
[2024-06-18 20:31:00,658: INFO/MainProcess] Events of group {task} enabled by remote.
[2024-06-18 20:41:54,350: INFO/MainProcess] Connected to redis://redis:6379/0
[2024-06-18 20:41:54,353: INFO/MainProcess] mingle: searching for neighbors
[2024-06-18 20:41:55,366: INFO/MainProcess] mingle: all alone
[2024-06-18 20:41:55,381: INFO/MainProcess] celery@3017dffa6c38 ready.
[2024-06-18 20:41:59,240: INFO/MainProcess] Events of group {task} enabled by remote.
[2024-06-18 21:00:20,846: INFO/MainProcess] Connected to redis://redis:6379/0
[2024-06-18 21:00:20,850: INFO/MainProcess] mingle: searching for neighbors
[2024-06-18 21:00:21,864: INFO/MainProcess] mingle: all alone
[2024-06-18 21:00:21,883: INFO/MainProcess] celery@96b77cdc9853 ready.
[2024-06-18 21:00:25,682: INFO/MainProcess] Events of group {task} enabled by remote.
[2024-06-18 21:01:07,285: INFO/MainProcess] Connected to redis://redis:6379/0
[2024-06-18 21:01:07,291: INFO/MainProcess] mingle: searching for neighbors
[2024-06-18 21:01:08,305: INFO/MainProcess] mingle: all alone
[2024-06-18 21:01:08,314: INFO/MainProcess] celery@5b31f34c757a ready.
[2024-06-18 21:01:12,409: INFO/MainProcess] Events of group {task} enabled by remote.
[2024-06-18 21:05:03,674: INFO/MainProcess] Connected to redis://redis:6379/0
[2024-06-18 21:05:03,678: INFO/MainProcess] mingle: searching for neighbors
[2024-06-18 21:05:04,694: INFO/MainProcess] mingle: all alone
[2024-06-18 21:05:04,709: INFO/MainProcess] celery@b899a826f3e1 ready.
[2024-06-18 21:05:08,625: INFO/MainProcess] Events of group {task} enabled by remote.
[2024-06-18 21:06:02,143: INFO/MainProcess] Connected to redis://redis:6379/0
[2024-06-18 21:06:02,147: INFO/MainProcess] mingle: searching for neighbors
[2024-06-18 21:06:03,155: INFO/MainProcess] mingle: all alone
[2024-06-18 21:06:03,162: INFO/MainProcess] celery@19b6aefe735b ready.
[2024-06-18 21:06:07,111: INFO/MainProcess] Events of group {task} enabled by remote.
[2024-06-18 21:17:36,693: INFO/MainProcess] Connected to redis://redis:6379/0
[2024-06-18 21:17:36,721: INFO/MainProcess] mingle: searching for neighbors
[2024-06-18 21:17:37,750: INFO/MainProcess] mingle: all alone
[2024-06-18 21:17:37,775: INFO/MainProcess] celery@5e1f02c6b7c7 ready.
[2024-06-18 21:17:41,549: INFO/MainProcess] Events of group {task} enabled by remote.
[2024-06-18 21:19:01,899: INFO/MainProcess] Connected to redis://redis:6379/0
[2024-06-18 21:19:01,903: INFO/MainProcess] mingle: searching for neighbors
[2024-06-18 21:19:02,914: INFO/MainProcess] mingle: all alone
[2024-06-18 21:19:02,925: INFO/MainProcess] celery@cb4fa09d1f87 ready.
[2024-06-18 21:19:06,763: INFO/MainProcess] Events of group {task} enabled by remote.
[2024-06-18 21:22:55,986: INFO/MainProcess] Connected to redis://redis:6379/0
[2024-06-18 21:22:55,988: INFO/MainProcess] mingle: searching for neighbors
[2024-06-18 21:22:56,994: INFO/MainProcess] mingle: all alone
[2024-06-18 21:22:57,005: INFO/MainProcess] celery@3475b410ae5b ready.
[2024-06-18 21:23:00,847: INFO/MainProcess] Events of group {task} enabled by remote.
[2024-06-18 21:29:41,698: ERROR/MainProcess] Received unregistered task of type 'test'.
The message has been ignored and discarded.

Did you remember to import the module containing this task?
Or maybe you're using relative imports?

Please see
https://docs.celeryq.dev/en/latest/internals/protocol.html
for more information.

The full contents of the message body was:
b'[[10, 5], {}, {"callbacks": null, "errbacks": null, "chain": null, "chord": null}]' (82b)

The full contents of the message headers:
{'lang': 'py', 'task': 'test', 'id': 'db070f54-7a1a-4938-a852-bb9b91014e0d', 'shadow': None, 'eta': None, 'expires': None, 'group': None, 'group_index': None, 'retries': 0, 'timelimit': [None, None], 'root_id': 'db070f54-7a1a-4938-a852-bb9b91014e0d', 'parent_id': None, 'argsrepr': '(10, 5)', 'kwargsrepr': '{}', 'origin': 'gen11@f6c63383f16a', 'ignore_result': False, 'replaced_task_nesting': 0, 'stamped_headers': None, 'stamps': {}}

The delivery info for this task is:
{'exchange': '', 'routing_key': 'celery'}
Traceback (most recent call last):
  File "/usr/local/lib/python3.12/site-packages/celery/worker/consumer/consumer.py", line 659, in on_task_received
    strategy = strategies[type_]
               ~~~~~~~~~~^^^^^^^
KeyError: 'test'
[2024-06-18 21:32:45,394: ERROR/MainProcess] Received unregistered task of type 'test'.
The message has been ignored and discarded.

Did you remember to import the module containing this task?
Or maybe you're using relative imports?

Please see
https://docs.celeryq.dev/en/latest/internals/protocol.html
for more information.

The full contents of the message body was:
b'[[10, 5], {}, {"callbacks": null, "errbacks": null, "chain": null, "chord": null}]' (82b)

The full contents of the message headers:
{'lang': 'py', 'task': 'test', 'id': '2230119a-ca32-4c7a-9dda-a79728513f59', 'shadow': None, 'eta': None, 'expires': None, 'group': None, 'group_index': None, 'retries': 0, 'timelimit': [None, None], 'root_id': '2230119a-ca32-4c7a-9dda-a79728513f59', 'parent_id': None, 'argsrepr': '(10, 5)', 'kwargsrepr': '{}', 'origin': 'gen11@f6c63383f16a', 'ignore_result': False, 'replaced_task_nesting': 0, 'stamped_headers': None, 'stamps': {}}

The delivery info for this task is:
{'exchange': '', 'routing_key': 'celery'}
Traceback (most recent call last):
  File "/usr/local/lib/python3.12/site-packages/celery/worker/consumer/consumer.py", line 659, in on_task_received
    strategy = strategies[type_]
               ~~~~~~~~~~^^^^^^^
KeyError: 'test'
[2024-06-18 21:32:46,454: ERROR/MainProcess] Received unregistered task of type 'test'.
The message has been ignored and discarded.

Did you remember to import the module containing this task?
Or maybe you're using relative imports?

Please see
https://docs.celeryq.dev/en/latest/internals/protocol.html
for more information.

The full contents of the message body was:
b'[[10, 5], {}, {"callbacks": null, "errbacks": null, "chain": null, "chord": null}]' (82b)

The full contents of the message headers:
{'lang': 'py', 'task': 'test', 'id': 'f0a86195-ea4f-43ac-ab9a-e9ee6aadee11', 'shadow': None, 'eta': None, 'expires': None, 'group': None, 'group_index': None, 'retries': 0, 'timelimit': [None, None], 'root_id': 'f0a86195-ea4f-43ac-ab9a-e9ee6aadee11', 'parent_id': None, 'argsrepr': '(10, 5)', 'kwargsrepr': '{}', 'origin': 'gen11@f6c63383f16a', 'ignore_result': False, 'replaced_task_nesting': 0, 'stamped_headers': None, 'stamps': {}}

The delivery info for this task is:
{'exchange': '', 'routing_key': 'celery'}
Traceback (most recent call last):
  File "/usr/local/lib/python3.12/site-packages/celery/worker/consumer/consumer.py", line 659, in on_task_received
    strategy = strategies[type_]
               ~~~~~~~~~~^^^^^^^
KeyError: 'test'
[2024-06-18 21:32:47,762: ERROR/MainProcess] Received unregistered task of type 'test'.
The message has been ignored and discarded.

Did you remember to import the module containing this task?
Or maybe you're using relative imports?

Please see
https://docs.celeryq.dev/en/latest/internals/protocol.html
for more information.

The full contents of the message body was:
b'[[10, 5], {}, {"callbacks": null, "errbacks": null, "chain": null, "chord": null}]' (82b)

The full contents of the message headers:
{'lang': 'py', 'task': 'test', 'id': '9e98edf9-595e-40a5-8a8b-6b075f723ae1', 'shadow': None, 'eta': None, 'expires': None, 'group': None, 'group_index': None, 'retries': 0, 'timelimit': [None, None], 'root_id': '9e98edf9-595e-40a5-8a8b-6b075f723ae1', 'parent_id': None, 'argsrepr': '(10, 5)', 'kwargsrepr': '{}', 'origin': 'gen11@f6c63383f16a', 'ignore_result': False, 'replaced_task_nesting': 0, 'stamped_headers': None, 'stamps': {}}

The delivery info for this task is:
{'exchange': '', 'routing_key': 'celery'}
Traceback (most recent call last):
  File "/usr/local/lib/python3.12/site-packages/celery/worker/consumer/consumer.py", line 659, in on_task_received
    strategy = strategies[type_]
               ~~~~~~~~~~^^^^^^^
KeyError: 'test'
[2024-06-18 21:36:02,834: INFO/MainProcess] Connected to redis://redis:6379/0
[2024-06-18 21:36:02,839: INFO/MainProcess] mingle: searching for neighbors
[2024-06-18 21:36:03,847: INFO/MainProcess] mingle: all alone
[2024-06-18 21:36:03,868: INFO/MainProcess] celery@9a018a57ef18 ready.
[2024-06-18 21:36:07,854: INFO/MainProcess] Events of group {task} enabled by remote.
[2024-06-18 21:36:41,039: ERROR/MainProcess] Received unregistered task of type 'test'.
The message has been ignored and discarded.

Did you remember to import the module containing this task?
Or maybe you're using relative imports?

Please see
https://docs.celeryq.dev/en/latest/internals/protocol.html
for more information.

The full contents of the message body was:
b'[[10, 5], {}, {"callbacks": null, "errbacks": null, "chain": null, "chord": null}]' (82b)

The full contents of the message headers:
{'lang': 'py', 'task': 'test', 'id': '1a5b2d55-eab0-4175-9ce0-9b06e2862bc1', 'shadow': None, 'eta': None, 'expires': None, 'group': None, 'group_index': None, 'retries': 0, 'timelimit': [None, None], 'root_id': '1a5b2d55-eab0-4175-9ce0-9b06e2862bc1', 'parent_id': None, 'argsrepr': '(10, 5)', 'kwargsrepr': '{}', 'origin': 'gen8@59c92aba2509', 'ignore_result': False, 'replaced_task_nesting': 0, 'stamped_headers': None, 'stamps': {}}

The delivery info for this task is:
{'exchange': '', 'routing_key': 'celery'}
Traceback (most recent call last):
  File "/usr/local/lib/python3.12/site-packages/celery/worker/consumer/consumer.py", line 659, in on_task_received
    strategy = strategies[type_]
               ~~~~~~~~~~^^^^^^^
KeyError: 'test'
[2024-06-18 21:42:50,046: INFO/MainProcess] Connected to redis://redis:6379/0
[2024-06-18 21:42:50,048: INFO/MainProcess] mingle: searching for neighbors
[2024-06-18 21:42:51,054: INFO/MainProcess] mingle: all alone
[2024-06-18 21:42:51,066: INFO/MainProcess] celery@103c8ebb4eb4 ready.
[2024-06-18 21:42:54,937: INFO/MainProcess] Events of group {task} enabled by remote.
[2024-06-18 21:42:56,481: ERROR/MainProcess] Received unregistered task of type 'test'.
The message has been ignored and discarded.

Did you remember to import the module containing this task?
Or maybe you're using relative imports?

Please see
https://docs.celeryq.dev/en/latest/internals/protocol.html
for more information.

The full contents of the message body was:
b'[[10, 5], {}, {"callbacks": null, "errbacks": null, "chain": null, "chord": null}]' (82b)

The full contents of the message headers:
{'lang': 'py', 'task': 'test', 'id': '4498e06c-d749-49b3-90ee-dcb1e1ea7606', 'shadow': None, 'eta': None, 'expires': None, 'group': None, 'group_index': None, 'retries': 0, 'timelimit': [None, None], 'root_id': '4498e06c-d749-49b3-90ee-dcb1e1ea7606', 'parent_id': None, 'argsrepr': '(10, 5)', 'kwargsrepr': '{}', 'origin': 'gen8@3b77cd6bbce2', 'ignore_result': False, 'replaced_task_nesting': 0, 'stamped_headers': None, 'stamps': {}}

The delivery info for this task is:
{'exchange': '', 'routing_key': 'celery'}
Traceback (most recent call last):
  File "/usr/local/lib/python3.12/site-packages/celery/worker/consumer/consumer.py", line 659, in on_task_received
    strategy = strategies[type_]
               ~~~~~~~~~~^^^^^^^
KeyError: 'test'
[2024-06-18 21:51:15,475: INFO/MainProcess] Connected to redis://redis:6379/0
[2024-06-18 21:51:15,477: INFO/MainProcess] mingle: searching for neighbors
[2024-06-18 21:51:16,489: INFO/MainProcess] mingle: all alone
[2024-06-18 21:51:16,508: INFO/MainProcess] celery@6ebea4c3c5b1 ready.
[2024-06-18 21:51:20,376: INFO/MainProcess] Events of group {task} enabled by remote.
[2024-06-18 21:51:23,372: INFO/MainProcess] Task pouet[2d6b0a06-df61-4220-b079-21be5c1e83e2] received
[2024-06-18 21:51:23,376: INFO/ForkPoolWorker-7] Task pouet[2d6b0a06-df61-4220-b079-21be5c1e83e2] succeeded in 0.002570958999967843s: 15
[2024-06-21 21:00:35,930: INFO/MainProcess] Connected to redis://redis:6379/0
[2024-06-21 21:00:35,967: INFO/MainProcess] mingle: searching for neighbors
[2024-06-21 21:00:37,005: INFO/MainProcess] mingle: all alone
[2024-06-21 21:00:37,021: INFO/MainProcess] celery@7a1ced37451d ready.
[2024-06-21 21:00:40,812: INFO/MainProcess] Events of group {task} enabled by remote.
[2024-06-21 21:39:05,737: INFO/MainProcess] Connected to redis://redis:6379/0
[2024-06-21 21:39:05,742: INFO/MainProcess] mingle: searching for neighbors
[2024-06-21 21:39:06,753: INFO/MainProcess] mingle: all alone
[2024-06-21 21:39:06,768: INFO/MainProcess] celery@61340a06348e ready.
[2024-06-21 21:39:10,511: INFO/MainProcess] Events of group {task} enabled by remote.
[2024-06-21 21:54:37,740: INFO/MainProcess] Connected to redis://redis:6379/0
[2024-06-21 21:54:37,745: INFO/MainProcess] mingle: searching for neighbors
[2024-06-21 21:54:38,752: INFO/MainProcess] mingle: all alone
[2024-06-21 21:54:38,759: INFO/MainProcess] celery@62c5950450ef ready.
[2024-06-21 21:54:42,569: INFO/MainProcess] Events of group {task} enabled by remote.
[2024-06-21 21:57:45,698: INFO/MainProcess] Task pouet[6f54f66a-9a1d-46a1-83a9-ad786628cd05] received
[2024-06-21 21:57:45,705: INFO/ForkPoolWorker-7] Task pouet[6f54f66a-9a1d-46a1-83a9-ad786628cd05] succeeded in 0.00424974999987171s: 8
[2024-06-22 15:05:11,410: INFO/MainProcess] Connected to redis://redis:6379/0
[2024-06-22 15:05:11,413: INFO/MainProcess] mingle: searching for neighbors
[2024-06-22 15:05:12,431: INFO/MainProcess] mingle: all alone
[2024-06-22 15:05:12,462: INFO/MainProcess] celery@4933c9558ffe ready.
[2024-06-22 15:05:16,222: INFO/MainProcess] Events of group {task} enabled by remote.
[2024-06-22 15:20:03,802: WARNING/MainProcess] consumer: Connection to broker lost. Trying to re-establish the connection...
Traceback (most recent call last):
  File "/usr/local/lib/python3.12/site-packages/celery/worker/consumer/consumer.py", line 340, in start
    blueprint.start(self)
  File "/usr/local/lib/python3.12/site-packages/celery/bootsteps.py", line 116, in start
    step.start(parent)
  File "/usr/local/lib/python3.12/site-packages/celery/worker/consumer/consumer.py", line 746, in start
    c.loop(*c.loop_args())
  File "/usr/local/lib/python3.12/site-packages/celery/worker/loops.py", line 97, in asynloop
    next(loop)
  File "/usr/local/lib/python3.12/site-packages/kombu/asynchronous/hub.py", line 373, in create_loop
    cb(*cbargs)
  File "/usr/local/lib/python3.12/site-packages/kombu/transport/redis.py", line 1344, in on_readable
    self.cycle.on_readable(fileno)
  File "/usr/local/lib/python3.12/site-packages/kombu/transport/redis.py", line 569, in on_readable
    chan.handlers[type]()
  File "/usr/local/lib/python3.12/site-packages/kombu/transport/redis.py", line 913, in _receive
    ret.append(self._receive_one(c))
               ^^^^^^^^^^^^^^^^^^^^
  File "/usr/local/lib/python3.12/site-packages/kombu/transport/redis.py", line 923, in _receive_one
    response = c.parse_response()
               ^^^^^^^^^^^^^^^^^^
  File "/usr/local/lib/python3.12/site-packages/redis/client.py", line 837, in parse_response
    response = self._execute(conn, try_read)
               ^^^^^^^^^^^^^^^^^^^^^^^^^^^^^
  File "/usr/local/lib/python3.12/site-packages/redis/client.py", line 813, in _execute
    return conn.retry.call_with_retry(
           ^^^^^^^^^^^^^^^^^^^^^^^^^^^
  File "/usr/local/lib/python3.12/site-packages/redis/retry.py", line 49, in call_with_retry
    fail(error)
  File "/usr/local/lib/python3.12/site-packages/redis/client.py", line 815, in <lambda>
    lambda error: self._disconnect_raise_connect(conn, error),
                  ^^^^^^^^^^^^^^^^^^^^^^^^^^^^^^^^^^^^^^^^^^^
  File "/usr/local/lib/python3.12/site-packages/redis/client.py", line 802, in _disconnect_raise_connect
    raise error
  File "/usr/local/lib/python3.12/site-packages/redis/retry.py", line 46, in call_with_retry
    return do()
           ^^^^
  File "/usr/local/lib/python3.12/site-packages/redis/client.py", line 814, in <lambda>
    lambda: command(*args, **kwargs),
            ^^^^^^^^^^^^^^^^^^^^^^^^
  File "/usr/local/lib/python3.12/site-packages/redis/client.py", line 835, in try_read
    return conn.read_response(disconnect_on_error=False, push_request=True)
           ^^^^^^^^^^^^^^^^^^^^^^^^^^^^^^^^^^^^^^^^^^^^^^^^^^^^^^^^^^^^^^^^
  File "/usr/local/lib/python3.12/site-packages/redis/connection.py", line 512, in read_response
    response = self._parser.read_response(disable_decoding=disable_decoding)
               ^^^^^^^^^^^^^^^^^^^^^^^^^^^^^^^^^^^^^^^^^^^^^^^^^^^^^^^^^^^^^
  File "/usr/local/lib/python3.12/site-packages/redis/_parsers/resp2.py", line 15, in read_response
    result = self._read_response(disable_decoding=disable_decoding)
             ^^^^^^^^^^^^^^^^^^^^^^^^^^^^^^^^^^^^^^^^^^^^^^^^^^^^^^
  File "/usr/local/lib/python3.12/site-packages/redis/_parsers/resp2.py", line 25, in _read_response
    raw = self._buffer.readline()
          ^^^^^^^^^^^^^^^^^^^^^^^
  File "/usr/local/lib/python3.12/site-packages/redis/_parsers/socket.py", line 115, in readline
    self._read_from_socket()
  File "/usr/local/lib/python3.12/site-packages/redis/_parsers/socket.py", line 68, in _read_from_socket
    raise ConnectionError(SERVER_CLOSED_CONNECTION_ERROR)
redis.exceptions.ConnectionError: Connection closed by server.
[2024-06-22 15:20:03,809: WARNING/MainProcess] /usr/local/lib/python3.12/site-packages/celery/worker/consumer/consumer.py:391: CPendingDeprecationWarning: 
In Celery 5.1 we introduced an optional breaking change which
on connection loss cancels all currently executed tasks with late acknowledgement enabled.
These tasks cannot be acknowledged as the connection is gone, and the tasks are automatically redelivered
back to the queue. You can enable this behavior using the worker_cancel_long_running_tasks_on_connection_loss
setting. In Celery 5.1 it is set to False by default. The setting will be set to True by default in Celery 6.0.

  warnings.warn(CANCEL_TASKS_BY_DEFAULT, CPendingDeprecationWarning)

[2024-06-22 15:20:03,825: ERROR/MainProcess] consumer: Cannot connect to redis://redis:6379/0: Error 111 connecting to redis:6379. Connection refused..
Trying again in 2.00 seconds... (1/100)

[2024-06-22 15:20:05,834: ERROR/MainProcess] consumer: Cannot connect to redis://redis:6379/0: Error -2 connecting to redis:6379. Name or service not known..
Trying again in 4.00 seconds... (2/100)

[2024-06-22 15:20:09,846: ERROR/MainProcess] consumer: Cannot connect to redis://redis:6379/0: Error -2 connecting to redis:6379. Name or service not known..
Trying again in 6.00 seconds... (3/100)

[2024-06-22 15:20:28,404: INFO/MainProcess] Connected to redis://redis:6379/0
[2024-06-22 15:20:28,406: INFO/MainProcess] mingle: searching for neighbors
[2024-06-22 15:20:29,411: INFO/MainProcess] mingle: all alone
[2024-06-22 15:20:29,417: INFO/MainProcess] celery@4a5ba6e9f5ae ready.
[2024-06-22 15:20:33,379: INFO/MainProcess] Events of group {task} enabled by remote.
[2024-06-22 16:47:50,821: INFO/MainProcess] Connected to redis://redis:6379/0
[2024-06-22 16:47:50,826: INFO/MainProcess] mingle: searching for neighbors
[2024-06-22 16:47:51,812: INFO/MainProcess] mingle: all alone
[2024-06-22 16:47:51,844: INFO/MainProcess] celery@a0709c2c2f99 ready.
[2024-06-22 16:47:55,656: INFO/MainProcess] Events of group {task} enabled by remote.
[2024-06-22 16:50:32,342: INFO/MainProcess] Connected to redis://redis:6379/0
[2024-06-22 16:50:32,345: INFO/MainProcess] mingle: searching for neighbors
[2024-06-22 16:50:33,355: INFO/MainProcess] mingle: all alone
[2024-06-22 16:50:33,386: INFO/MainProcess] celery@cc6c97aa8e7a ready.
[2024-06-22 16:50:37,188: INFO/MainProcess] Events of group {task} enabled by remote.
[2024-06-22 16:52:24,543: INFO/MainProcess] Connected to redis://redis:6379/0
[2024-06-22 16:52:24,545: INFO/MainProcess] mingle: searching for neighbors
[2024-06-22 16:52:25,551: INFO/MainProcess] mingle: all alone
[2024-06-22 16:52:25,558: INFO/MainProcess] celery@f80272a9928b ready.
[2024-06-22 16:52:29,457: INFO/MainProcess] Events of group {task} enabled by remote.
[2024-06-22 17:02:28,835: INFO/MainProcess] Connected to redis://redis:6379/0
[2024-06-22 17:02:28,838: INFO/MainProcess] mingle: searching for neighbors
[2024-06-22 17:02:29,866: INFO/MainProcess] mingle: all alone
[2024-06-22 17:02:29,900: INFO/MainProcess] celery@5323439a4d68 ready.
[2024-06-22 17:02:33,729: INFO/MainProcess] Events of group {task} enabled by remote.
[2024-06-22 17:02:47,639: INFO/MainProcess] Connected to redis://redis:6379/0
[2024-06-22 17:02:47,643: INFO/MainProcess] mingle: searching for neighbors
[2024-06-22 17:02:48,653: INFO/MainProcess] mingle: all alone
[2024-06-22 17:02:48,665: INFO/MainProcess] celery@23a1a6b5c734 ready.
[2024-06-22 17:02:52,638: INFO/MainProcess] Events of group {task} enabled by remote.
[2024-06-22 17:07:10,131: INFO/MainProcess] Connected to redis://redis:6379/0
[2024-06-22 17:07:10,138: INFO/MainProcess] mingle: searching for neighbors
[2024-06-22 17:07:11,157: INFO/MainProcess] mingle: all alone
[2024-06-22 17:07:11,172: INFO/MainProcess] celery@d46330c86ba2 ready.
[2024-06-22 17:07:15,057: INFO/MainProcess] Events of group {task} enabled by remote.
[2024-06-22 17:20:29,404: INFO/MainProcess] Connected to redis://redis:6379/0
[2024-06-22 17:20:29,406: INFO/MainProcess] mingle: searching for neighbors
[2024-06-22 17:20:30,413: INFO/MainProcess] mingle: all alone
[2024-06-22 17:20:30,424: INFO/MainProcess] celery@7165f7bd7b46 ready.
[2024-06-22 17:20:34,283: INFO/MainProcess] Events of group {task} enabled by remote.
[2024-06-22 17:34:56,865: INFO/MainProcess] Connected to redis://redis:6379/0
[2024-06-22 17:34:56,871: INFO/MainProcess] mingle: searching for neighbors
[2024-06-22 17:34:57,882: INFO/MainProcess] mingle: all alone
[2024-06-22 17:34:57,890: INFO/MainProcess] celery@c70695f3e490 ready.
[2024-06-22 17:35:01,755: INFO/MainProcess] Events of group {task} enabled by remote.
[2024-06-22 17:44:03,938: INFO/MainProcess] Task pouet[ea0406fc-7c0e-4bb2-95c6-0ccaf8baeade] received
[2024-06-22 17:44:03,951: INFO/ForkPoolWorker-7] Task pouet[ea0406fc-7c0e-4bb2-95c6-0ccaf8baeade] succeeded in 0.006811832994571887s: 30
